Traceback (most recent call last):
  File "skema/program_analysis/model_coverage_report/model_coverage_report.py", line 76, in generate_data_product
    output = func_timeout(10, data_product_function, args=args, kwargs=kwargs)
  File "/opt/hostedtoolcache/Python/3.8.18/x64/lib/python3.8/site-packages/func_timeout/dafunc.py", line 108, in func_timeout
    raise_exception(exception)
  File "/opt/hostedtoolcache/Python/3.8.18/x64/lib/python3.8/site-packages/func_timeout/py3_raise.py", line 7, in raise_exception
    raise exception[0] from None
  File "skema/program_analysis/model_coverage_report/model_coverage_report.py", line 106, in generate_cast
    cast = python_to_cast(source_path, cast_obj=True)
  File "/opt/hostedtoolcache/Python/3.8.18/x64/lib/python3.8/site-packages/skema/program_analysis/python2cast.py", line 85, in python_to_cast
    python3_source = preprocess(python2_source)
  File "/opt/hostedtoolcache/Python/3.8.18/x64/lib/python3.8/site-packages/skema/program_analysis/python_preprocessor.py", line 6, in preprocess
    return convert_python2_to_python3(source)
  File "/opt/hostedtoolcache/Python/3.8.18/x64/lib/python3.8/site-packages/skema/program_analysis/python_preprocessor.py", line 15, in convert_python2_to_python3
    subprocess.run(['2to3', '--write', '--nobackups', str(temp_file_path)], check=True)
  File "/opt/hostedtoolcache/Python/3.8.18/x64/lib/python3.8/subprocess.py", line 516, in run
    raise CalledProcessError(retcode, process.args,
subprocess.CalledProcessError: Command '['2to3', '--write', '--nobackups', '/tmp/tmpfyeqyc37.py']' returned non-zero exit status 1.
